Workbook

Sheet المدخلات
A1: مدخلات النموذج — عدّل القيم الصفراء وسيتحدّث كل شيء تلقائياً
A3: البيان | B3: القيمة | C3: الوحدة | D3: ملاحظة
A4: أسابيع النشر في السنة | B4: 48 | C4: أسبوع | D4: 4 أسابيع إجازات
A5: محاضرات في الأسبوع | B5: 4 | C5: محاضرة | D5: ثابت حسب الطلب
A6: ساعات المحاضرة الواحدة | B6: 2 | C6: ساعة | D6: ثابت حسب الطلب
A7: عدد الطلاب النشطين | B7: 2000 | C7: طالب | D7: افتراض
A8: ساعات المشاهدة / طالب / شهر | B8: 12 | C8: ساعة | D8: ≈35% من المحتوى المنشور
A9: حجم كل الجودات معاً (480+720+1080+صوت) | B9: 3.75 | C9: GB/ساعة | D9: ≈8.3 Mbps إجمالي
A10: متوسط مدة بقاء الفيديو على R2 | B10: 6 | C10: شهر | D10: تراكم سنة ثم حذف → متوسط 6 شهور
A11: معدل بث المشاهدة الافتراضي (720p) | B11: 2.5 | C11: Mbps | D11: لحساب حجم التوصيل
A12: طول شريحة HLS | B12: 5 | C12: ثانية | D12: يحدّد عدد الكائنات
A13: نسبة القراءات من كاش الحافة | B13: 0.85 | C13: نسبة | D13: Cache-Control: immutable
A14: سعر تخزين R2 | B14: 0.015 | C14: $/GB-شهر | D14: Standard storage
A15: سعر سحب Bunny (أوروبا/أمريكا) | B15: 0.01 | C15: $/GB | D15: Standard network
... A19: حساب Google Play | B19: 25 | C19: $ لمرة واحدة | D19: السنة الأولى فقط
A21: حسابات مشتقّة
A22: محاضرات / سنة | B22: ='المدخلات'!$B$4*'المدخلات'!$B$5 | C22: —
A23: ساعات محتوى / سنة | B23: =B22*'المدخلات'!$B$6 | C23: —
A24: دقائق محتوى / سنة | B24: =B23*60 | C24: —
A25: حجم المحاضرة الواحدة (GB) | B25: ='المدخلات'!$B$6*'المدخلات'!$B$9 | C25: —
A26: حجم المحتوى السنوي (GB) | B26: =B22*B25 | C26: —
A27: ذروة التخزين بنهاية السنة (TB) | B27: =B26/1000 | C27: —
A28: شرائح / محاضرة (4 مسارات) | B28: =3600/'المدخلات'!$B$12*'المدخلات'!$B$6*4 | C28: —
A29: كائنات مكتوبة على R2 / سنة | B29: =B22*(B28+8) | C29: —
A30: حجم التوصيل للطلاب (TB/سنة) | B30: ='المدخلات'!$B$7*'المدخلات'!$B$8*('المدخلات'!$B$11/8*3600/1000)*12/1000 | C30: —
A31: قراءات الشرائح / شهر | B31: ='المدخلات'!$B$7*'المدخلات'!$B$8*3600/'المدخلات'!$B$12 | C31: —

Sheet التكلفة_السنوية
A1: التكلفة السنوية التفصيلية — السنة الأولى (بالدولار)
A3: البند | B3: الخدمة | C3: التكلفة السنوية ($) | D3: ملاحظة
A4: باقة Workers المدفوعة | B4: Cloudflare Workers | C4: ='المدخلات'!$B$17*12 | D4: 10M طلب + 30M CPU-ms شهرياً — مطلوبة لرفع حد الـ subrequests إلى 1000
A5: تخزين شرائح الفيديو HLS | B5: Cloudflare R2 | C5: =MAX(0,('المدخلات'!$B$26*'المدخلات'!$B$10/12)-10)*'المدخلات'!$B$14*12 | D5: البند الأكبر — ينمو كل شهر ثم يُصفَّر بنهاية السنة
A6: عمليات كتابة (Class A) | B6: Cloudflare R2 | C6: =0 | D6: ≈1.1M كائن/سنة — ضمن المجاني (1M/شهر)
A7: عمليات قراءة (Class B) | B7: Cloudflare R2 | C7: =MAX(0,'المدخلات'!$B$31*(1-'المدخلات'!$B$13)-10000000)/1000000*0.36*12 | D7: ضمن المجاني (10M/شهر) بفضل كاش الحافة
A8: قاعدة البيانات (كورسات/دروس/تقدم/كويزات/أسئلة) | B8: Cloudflare D1 | C8: =0 | D8: 25 مليار صف قراءة + 50 مليون كتابة + 5GB مجاناً
A9: مفاتيح التشفير + تتبّع النقل | B9: Cloudflare KV | C9: =0 | D9: 10M قراءة + 1M كتابة مجاناً شهرياً
A10: طابور نقل الفيديو | B10: Cloudflare Queues | C10: =0 | D10: 1M عملية مجاناً شهرياً
A11: لوحة المدرس + ويب الطلاب | B11: Cloudflare Pages | C11: =0 | D11: استضافة ونطاقات وبناء مجاني
A12: تحويل صور الأغلفة | B12: Cloudflare Images | C12: =0 | D12: 5000 تحويلة فريدة مجاناً شهرياً
A13: الترميز السحابي (حتى 1080p) | B13: Bunny Stream | C13: =0 | D13: الترميز القياسي مجاني — Premium فقط بفلوس
A14: سحب الشرائح من Bunny + تخزين مؤقت | B14: Bunny Stream | C14: =MAX(12,'المدخلات'!$B$26*1.05*'المدخلات'!$B$15+'المدخلات'!$B$26*1.5*(2/30)*0.01) | D14: الحد الأدنى للاستهلاك 1$/شهر
A15: المصادقة (JWT) | B15: Supabase Auth | C15: =0 | D15: مجاني حتى 50,000 مستخدم نشط شهرياً
A16: إشعارات Push | B16: Firebase FCM | C16: =0 | D16: FCM مجاني بالكامل
A17: تجديد النطاق | B17: Domain | C17: ='المدخلات'!$B$18 | D17: نطاق واحد
A18: حساب Google Play | B18: Google Play | C18: ='المدخلات'!$B$19 | D18: مرة واحدة — السنة الأولى فقط
A19: الإجمالي — السنة الأولى | C19: =SUM(C4:C18)
A20: الإجمالي — السنوات التالية (بدون رسوم Play) | C20: ='التكلفة_السنوية'!$C$19-'المدخلات'!$B$19
A22: المتوسط الشهري (السنة الأولى) | C22: ='التكلفة_السنوية'!$C$19/12
A23: تكلفة الطالب الواحد / سنة | C23: ='التكلفة_السنوية'!$C$19/'المدخلات'!$B$7
A24: تكلفة ساعة المحاضرة الواحدة | C24: ='التكلفة_السنوية'!$C$19/'المدخلات'!$B$23
A25: تكلفة التيرابايت المُسلَّم للطلاب | C25: ='التكلفة_السنوية'!$C$19/'المدخلات'!$B$30

Sheet التدفق_الشهري
A1: التدفق الشهري للسنة الأولى (بالدولار)
A3: الشهر | B3: التخزين التراكمي (GB) | C3: تكلفة التخزين | D3: Workers | E3: Bunny | F3: إجمالي الشهر
A4: شهر 1 | B4: =('المدخلات'!$B$26/12)*(0)+('المدخلات'!$B$26/24) | C4: =MAX(0,B4-10)*'المدخلات'!$B$14 | D4: ='المدخلات'!$B$17 | E4: =('المدخلات'!$B$26*1.05*'المدخلات'!$B$15+'المدخلات'!$B$26*1.5*(2/30)*0.01)/12 | F4: =SUM(C4:E4)
A5: شهر 2 | B5: =('المدخلات'!$B$26/12)*(1)+('المدخلات'!$B$26/24) | C5: =MAX(0,B5-10)*'المدخلات'!$B$14 | D5: ='المدخلات'!$B$17 | E5: =('المدخلات'!$B$26*1.05*'المدخلات'!$B$15+'المدخلات'!$B$26*1.5*(2/30)*0.01)/12 | F5: =SUM(C5:E5)
A6: شهر 3 | B6: =('المدخلات'!$B$26/12)*(2)+('المدخلات'!$B$26/24) | C6: =MAX(0,B6-10)*'المدخلات'!$B$14 | D6: ='المدخلات'!$B$17 | E6: =('المدخلات'!$B$26*1.05*'المدخلات'!$B$15+'المدخلات'!$B$26*1.5*(2/30)*0.01)/12 | F6: =SUM(C6:E6)
A7: شهر 4 | B7: =('المدخلات'!$B$26/12)*(3)+('المدخلات'!$B$26/24) | C7: =MAX(0,B7-10)*'المدخلات'!$B$14 | D7: ='المدخلات'!$B$17 | E7: =('المدخلات'!$B$26*1.05*'المدخلات'!$B$15+'المدخلات'!$B$26*1.5*(2/30)*0.01)/12 | F7: =SUM(C7:E7)
A8: شهر 5 | B8: =('المدخلات'!$B$26/12)*(4)+('المدخلات'!$B$26/24) | C8: =MAX(0,B8-10)*'المدخلات'!$B$14 | D8: ='المدخلات'!$B$17 | E8: =('المدخلات'!$B$26*1.05*'المدخلات'!$B$15+'المدخلات'!$B$26*1.5*(2/30)*0.01)/12 | F8: =SUM(C8:E8)
A9: شهر 6 | B9: =('المدخلات'!$B$26/12)*(5)+('المدخلات'!$B$26/24) | C9: =MAX(0,B9-10)*'المدخلات'!$B$14 | D9: ='المدخلات'!$B$17 | E9: =('المدخلات'!$B$26*1.05*'المدخلات'!$B$15+'المدخلات'!$B$26*1.5*(2/30)*0.01)/12 | F9: =SUM(C9:E9)
A10: شهر 7 | B10: =('المدخلات'!$B$26/12)*(6)+('المدخلات'!$B$26/24) | C10: =MAX(0,B10-10)*'المدخلات'!$B$14 | D10: ='المدخلات'!$B$17 | E10: =('المدخلات'!$B$26*1.05*'المدخلات'!$B$15+'المدخلات'!$B$26*1.5*(2/30)*0.01)/12 | F10: =SUM(C10:E10)
A11: شهر 8 | B11: =('المدخلات'!$B$26/12)*(7)+('المدخلات'!$B$26/24) | C11: =MAX(0,B11-10)*'المدخلات'!$B$14 | D11: ='المدخلات'!$B$17 | E11: =('المدخلات'!$B$26*1.05*'المدخلات'!$B$15+'المدخلات'!$B$26*1.5*(2/30)*0.01)/12 | F11: =SUM(C11:E11)
A12: شهر 9 | B12: =('المدخلات'!$B$26/12)*(8)+('المدخلات'!$B$26/24) | C12: =MAX(0,B12-10)*'المدخلات'!$B$14 | D12: ='المدخلات'!$B$17 | E12: =('المدخلات'!$B$26*1.05*'المدخلات'!$B$15+'المدخلات'!$B$26*1.5*(2/30)*0.01)/12 | F12: =SUM(C12:E12)
A13: شهر 10 | B13: =('المدخلات'!$B$26/12)*(9)+('المدخلات'!$B$26/24) | C13: =MAX(0,B13-10)*'المدخلات'!$B$14 | D13: ='المدخلات'!$B$17 | E13: =('المدخلات'!$B$26*1.05*'المدخلات'!$B$15+'المدخلات'!$B$26*1.5*(2/30)*0.01)/12 | F13: =SUM(C13:E13)
A14: شهر 11 | B14: =('المدخلات'!$B$26/12)*(10)+('المدخلات'!$B$26/24) | C14: =MAX(0,B14-10)*'المدخلات'!$B$14 | D14: ='المدخلات'!$B$17 | E14: =('المدخلات'!$B$26*1.05*'المدخلات'!$B$15+'المدخلات'!$B$26*1.5*(2/30)*0.01)/12 | F14: =SUM(C14:E14)
A15: شهر 12 | B15: =('المدخلات'!$B$26/12)*(11)+('المدخلات'!$B$26/24) | C15: =MAX(0,B15-10)*'المدخلات'!$B$14 | D15: ='المدخلات'!$B$17 | E15: =('المدخلات'!$B$26*1.05*'المدخلات'!$B$15+'المدخلات'!$B$26*1.5*(2/30)*0.01)/12 | F15: =SUM(C15:E15)
A16: الإجمالي | C16: =SUM(C4:C15) | D16: =SUM(D4:D15) | E16: =SUM(E4:E15) | F16: =SUM(F4:F15)

Sheet السيناريوهات
A1: تحليل الحساسية — تأثير كل متغير على التكلفة السنوية
A3: السيناريو | B3: السنة الأولى ($) | C3: السنوات التالية ($) | D3: السبب
A4: الأساس: 2,000 طالب + تراكم سنة ثم حذف | B4: 244.36 | C4: 219.36 | D4: المرجع
A5: 500 طالب فقط | B5: 244.36 | C5: 219.36 | D5: التكلفة لا تتأثر بعدد الطلاب: الخارج من R2 مجاني
A6: 10,000 طالب | B6: 257.15 | C6: 232.15 | D6: +13$ فقط (تجاوز طلبات Workers وقراءات R2)
A7: احتفاظ متحرك 12 شهراً (1.44 TB مستقر) | B7: 398.96 | C7: 373.96 | D7: تخزين 1.44TB طول السنة = 259$/سنة
A8: أرشيف دائم بلا حذف — السنة 2 | B8: 244.36 | C8: 503.56 | D8: السنة 1 = 244$، السنة 2 = 504$، السنة 3 = 763$
A9: ترميز Bunny Premium 1080p (بدل المجاني) | B9: 1396.36 | C9: 1371.36 | D9: +0.05$/دقيقة
A10: ترميز Bunny Premium 4K | B10: 3700.36 | C10: 3675.36 | D10: +0.15$/دقيقة — غير مُوصى به
A11: سحب الشرائح بتسعير الشرق الأوسط (0.06$/GB) | B11: 319.96 | C11: 294.96 | D11: بدّل لباقة Volume (0.005$/GB)
A12: Supabase Pro (بدل المجاني) | B12: 544.36 | C12: 519.36 | D12: اختياري: عدم الإيقاف التلقائي + SMTP مخصص
A13: الحد الأقصى المتحفظ (كل الباقات المدفوعة) | B13: 651 | C13: 626 | D13: أسوأ تسعير + بدون كاش + Supabase Pro

Sheet مقارنة_البدائل
A1: مقارنة: التصميم الحالي (Bunny → R2) مقابل البدائل — 2,000 طالب / 12 ساعة مشاهدة
A3: البديل | B3: التخزين/السعة | C3: التوصيل | D3: خدمات ثابتة | E3: الإجمالي السنوي ($)
A4: الحالي: Bunny Stream (ترميز مجاني) + R2 | B4: 127.8 | C4: 0 | D4: 116.56 | E4: 244.36
A5: Cloudflare Stream (بدون R2) | B5: 748.8 | C5: 17280 | D5: 100 | E5: 18128.8
A6: CDN تقليدي بـ 0.05$/GB (مثل Bunny/Bunny CDN مباشر) | B6: 127.8 | C6: 16200 | D6: 100 | E6: 16427.8
A7: S3 + CloudFront بـ 0.09$/GB | B7: 190 | C7: 29160 | D7: 100 | E7: 29450
A9: الوفر السنوي مقابل Cloudflare Stream | E9: 17884.44
A10: نسبة الوفر | E10: 98.7%

Sheet خريطة_المزايا
A1: كل ميزة في المنصة ← الخدمة التي تستهلكها ← تكلفتها السنوية
A3: الميزة | B3: الخدمة | C3: التكلفة السنوية ($) | D3: ملاحظة
A4: تسجيل الدخول / المصادقة / استرجاع كلمة المرور | B4: Supabase Auth | C4: 0 | D4: مجاني حتى 50 ألف مستخدم نشط
A5: تصفّح الكورسات والوحدات والدروس | B5: Workers + D1 | C5: 0 | D5: ضمن الباقة المدفوعة
A6: البحث الداخلي (SQLite FTS5) | B6: D1 | C6: 0 | D6: ضمن الباقة
A7: أكواد التفعيل وإدارتها | B7: D1 | C7: 0 | D7: ضمن الباقة
A8: تتبّع التقدّم + نبضات المشاهدة (Heartbeat) | B8: Workers + D1 | C8: 0 | D8: ≈1.7M طلب/شهر — ضمن 10M
A9: رفع الفيديو وترميزه (480p/720p/1080p) | B9: Bunny Stream | C9: 0 | D9: الترميز القياسي مجاني
A10: نقل الشرائح وتشفيرها AES-128 إلى R2 | B10: Queues + Workers + KV | C10: 0 | D10: ضمن المجاني
A11: تخزين الفيديو وبثه HLS | B11: R2 (+ كاش الحافة) | C11: 127.8 | D11: البند الوحيد المؤثر
A12: حماية الفيديو (علامة مائية، ربط جهاز، توكنات) | B12: Workers + KV + D1 | C12: 0 | D12: ضمن الباقة
A13: ملفات PDF والمرفقات | B13: R2 | C13: 0 | D13: ≈2GB/سنة
A14: الأسئلة والإجابات والتقييمات | B14: D1 | C14: 0 | D14: ضمن الباقة
A15: الكويزات ونتائجها | B15: D1 | C15: 0 | D15: ضمن الباقة
... A23: تطبيق أندرويد | B23: Google Play | C23: 25 | D23: مرة واحدة
A24: الإجمالي | C24: =SUM(C4:C23)

Sheet سيناريو_مونجو
A1: سيناريو بديل: MongoDB بدل D1 + تخزين Bunny بـ $0.055/GB (100 جيجا/شهر)
A3: السيناريو | B3: قاعدة البيانات | C3: تخزين الفيديو | D3: توصيل/سحب | E3: خدمات ثابتة | F3: الإجمالي/سنة ($) | G3: الفرق عن التصميم الحالي
A4: التصميم الحالي (D1 + R2) | B4: D1 — $0 | C4: R2 — 127.80 | D4: سحب Bunny — 15.12 | E4: 100.00 | F4: 244.36 | G4: المرجع
A5: B1: MongoDB Flex + نفس الكود (نقل لـ R2) | B5: Flex — 144.00 | C5: Bunny 66.00 + R2 127.80 | D5: 15.12 | E5: 100.00 | F5: 452.92 | G5: +209 $ (+85%)
A6: B2: MongoDB M10 + نفس الكود (نقل لـ R2) | B6: M10 — 900.00 | C6: Bunny 66.00 + R2 127.80 | D6: 15.12 | E6: 100.00 | F6: 1208.92 | G6: +965 $ (+395%)
A7: B3: MongoDB Flex + كل الفيديو على Bunny (Volume 0.005$/GB) | B7: Flex — 144.00 | C7: Bunny كامل — 429.0 | D7: 1620.0 | E7: 100.00 | F7: 2293 | G7: +2,049 $ (+838%)
A8: B4: MongoDB M10 + كل الفيديو على Bunny (الشرق الأوسط 0.06$/GB) | B8: M10 — 900.00 | C8: Bunny كامل — 429.0 | D8: 19440.0 | E8: 100.00 | F8: 20869 | G8: +20,625 $ (+8440%)
A11: أسعار MongoDB Atlas (2026)
A12: الطبقة | B12: السعر/شهر | C12: التخزين | D12: الحد الأقصى | E12: ملاحظة
A13: M0 (مجاني) | B13: $0 | C13: 512 MB | D13: ~100 عملية/ثانية | E13: بدون نسخ احتياطي — مش هتكفي بعد شهرين
A14: Flex | B14: $8 → $30 (سقف) | C14: 5 GB | D14: ~500 عملية/ثانية | E14: مناسبة للحمولة الحالية (≈0.7 طلب/ثانية)
A15: M10 (مخصّص) | B15: $58.4 + تخزين/نسخ ≈ $75-85 | C15: 10-128 GB | D15: 1,500 اتصال | E15: إنتاج حقيقي + PITR + Atlas Search
A16: M20 | B16: ≈ $146 | C16: 20 GB+ | D16: — | E16: مبالغة في حالتنا
A18: ملاحظة معمارية: Cloudflare Workers تقدر تتصل بـ MongoDB بالدريفر الرسمي (node:net + node:tls مدعومين من 2025)، لكن Atlas Data API مُلغاة، ومفيش Hyperdrive لـ Mongo.

Sheet B1_التفاصيل
A1: تفاصيل سيناريو B1: MongoDB Flex + نفس الكود (ترميز Bunny ← نقل لـ R2)
A3: البند | B3: وحدة التسعير | C3: الاستهلاك السنوي المتوقع | D3: التكلفة/سنة ($) | E3: ملاحظة
A4: Cloudflare Workers — الباقة المدفوعة | B4: 5$/شهر (10M طلب + 30M CPU-ms) | C4: 1.74M طلب/شهر | D4: 60
A5: MongoDB Atlas Flex — قاعدة البيانات بدل D1 | B5: 8$ أساس (حتى 100 عملية/ثانية) — سقف صلب 30$ | C5: ≈2-3 عملية/ثانية، ذروة في مواسم الامتحانات | D5: 144 | E5: بديل عن D1 (كانت $0)
A6: Atlas Flex — التخزين | B6: 5 GB مشمولة | C6: حجم البيانات المتوقع سنة 1 ≈ 0.5-1 GB | D6: 0
A7: Atlas Flex — نقل البيانات (Egress) | B7: غير محدود ومجاني على Flex | C7: ≈3 GB/شهر | D7: 0
A8: Cloudflare R2 — تخزين شرائح الفيديو | B8: 0.015$/GB-شهر | C8: 8,640 GB-شهر − 120 GB مجانية | D8: 127.8
A9: Cloudflare R2 — عمليات Class A (كتابة) | B9: 4.50$/مليون | C9: 1.1M كائن/سنة (~92k/شهر) — ضمن 1M مجاناً | D9: 0
A10: Cloudflare R2 — عمليات Class B (قراءة) | B10: 0.36$/مليون | C10: 17.3M قراءة/شهر، 15% بيفوت الكاش — ضمن 10M | D10: 0
A11: Cloudflare R2 — الخارج (توصيل الطلاب) | B11: مجاني تماماً | C11: 324 TB/سنة | D11: 0
A12: Bunny Stream — الترميز القياسي | B12: مجاني حتى 1080p | C12: 23,040 دقيقة/سنة | D12: 0
A13: Bunny Stream — التخزين | B13: 0.055$/GB-شهر | C13: 100 GB مقيم/شهر | D13: 66
A14: Bunny Stream — سحب الشرائح للـ Worker | B14: 0.010$/GB (أوروبا/أمريكا) | C14: 1,512 GB/سنة | D14: 15.12
A15: Cloudflare Queues | B15: 0.40$/مليون بعد 1M | C15: ≈1M عملية/سنة | D15: 0
A16: Cloudflare KV | B16: مفاتيح التشفير + تتبّع النقل | C16: ≈20k كتابة/سنة | D16: 0
A17: Cloudflare Pages | B17: لوحة المدرس + ويب الطلاب | C17: طلبات غير محدودة | D17: 0
... A22: حساب Google Play | B22: مرة واحدة — السنة الأولى | C22: — | D22: 25
A23: الإجمالي — السنة الأولى | D23: =SUM(D4:D22)
A24: الإجمالي — السنوات التالية | D24: =D23-25
A25: المتوسط الشهري (السنة الأولى) | D25: =D23/12
A26: تكلفة الطالب / سنة | D26: =D23/2000
A29: حساسية سعر MongoDB Atlas Flex
A30: الحالة | B30: سعر Flex/شهر | C30: التكلفة/سنة ($) | D30: إجمالي B1/سنة ($) | E30: ملاحظة
A31: متفائل — تحت 100 عملية/ثانية طول الوقت | B31: 8 | C31: 96 | D31: 404.92 | E31: الحد الأدنى الفعلي لـ Flex
A32: الأساس — ذروات موسمية تدخل شريحة 100-200 | B32: 12 | C32: 144 | D32: 452.92 | E32: الفرضية المعتمدة في الجدول أعلاه
A33: السقف — 400-500 عملية/ثانية | B33: 30 | C33: 360 | D33: 668.92 | E33: سقف صلب: Flex لا يمكن أن يتجاوز 30$/شهر أبداً
A36: التدفق الشهري لسيناريو B1 (السنة الأولى)
A37: الشهر | B37: Workers | C37: MongoDB Flex | D37: Bunny | E37: تخزين R2 | F37: نطاق | G37: إجمالي الشهر
A38: شهر 1 | B38: 5 | C38: 12 | D38: 6.76 | E38: 0.75 | F38: 1.25 | G38: =SUM(B38:F38)
A39: شهر 2 | B39: 5 | C39: 12 | D39: 6.76 | E39: 2.55 | F39: 1.25 | G39: =SUM(B39:F39)
A40: شهر 3 | B40: 5 | C40: 12 | D40: 6.76 | E40: 4.35 | F40: 1.25 | G40: =SUM(B40:F40)
A41: شهر 4 | B41: 5 | C41: 12 | D41: 6.76 | E41: 6.15 | F41: 1.25 | G41: =SUM(B41:F41)
A42: شهر 5 | B42: 5 | C42: 12 | D42: 6.76 | E42: 7.95 | F42: 1.25 | G42: =SUM(B42:F42)
A43: شهر 6 | B43: 5 | C43: 12 | D43: 6.76 | E43: 9.75 | F43: 1.25 | G43: =SUM(B43:F43)
A44: شهر 7 | B44: 5 | C44: 12 | D44: 6.76 | E44: 11.55 | F44: 1.25 | G44: =SUM(B44:F44)
A45: شهر 8 | B45: 5 | C45: 12 | D45: 6.76 | E45: 13.35 | F45: 1.25 | G45: =SUM(B45:F45)
A46: شهر 9 | B46: 5 | C46: 12 | D46: 6.76 | E46: 15.15 | F46: 1.25 | G46: =SUM(B46:F46)
A47: شهر 10 | B47: 5 | C47: 12 | D47: 6.76 | E47: 16.95 | F47: 1.25 | G47: =SUM(B47:F47)
A48: شهر 11 | B48: 5 | C48: 12 | D48: 6.76 | E48: 18.75 | F48: 1.25 | G48: =SUM(B48:F48)
A49: شهر 12 | B49: 5 | C49: 12 | D49: 6.76 | E49: 20.55 | F49: 1.25 | G49: =SUM(B49:F49)
...

Sheet باقة_700
A1: إزاي نوصل للتكلفة إلى قرابة 700$/سنة — رافعات وباقات مقترحة
A2: نقطة البداية (التصميم الحالي، السنوات التالية) = $219.36/سنة
A4: أولاً: قائمة الرافعات (اختار منها)
A5: الرافعة (الخدمة) | B5: التكلفة/سنة ($) | C5: إيه اللي بتضيفه | D5: الأولوية
A6: Supabase Pro (بدل المجاني) | B6: 300 | C6: يلغي خطر إيقاف المشروع المجاني + SMTP مخصص + نسخ احتياطي يومي + دعم | D6: عالية
A7: Cloudflare Pro للنطاق ($20/شهر) | B7: 240 | C7: WAF مُدار + قواعد صفحات + تحسين صور + دعم 24/7 | D7: متوسطة
A8: Apple Developer (تطبيق iOS) | B8: 99 | C8: لازم لو هتنزّل التطبيق على App Store | D8: حسب الحاجة
A9: مراقبة Uptime + Logs (Better Stack $10/شهر) | B9: 120 | C9: تنبيه قبل ما الطلاب يشتكوا — يراقب الـ API والـ Worker | D9: متوسطة
A10: Sentry Developer ($26/شهر) | B10: 312 | C10: تتبّع أخطاء التطبيق — المجاني (5k خطأ/شهر) يكفي غالباً | D10: منخفضة
A11: MongoDB Atlas Flex (بدل D1) | B11: 144 | C11: فقط لو فريقك أريح مع Mongo — D1 بـ $0 وأسرع | D11: اختياري
A12: تخزين Bunny 100GB ($0.055/GB) | B12: 66 | C12: نسخة احتياطية من الفيديو + إمكانية إعادة النقل | D12: متوسطة
A13: نسخ احتياطي D1 → R2 (كرون يومي) | B13: 2 | C13: أرخص وأهم بند أمان في القائمة | D13: عالية
A14: Resend / SMTP للإيميلات ($20/شهر) | B14: 240 | C14: إيميلات التفعيل واسترجاع كلمة المرور — المجاني 3k/شهر يكفي | D14: منخفضة
A15: هامش طوارئ 10% | B15: 22 | C15: لأي تجاوز غير متوقع | D15: موصى به
A18: ثانياً: باقات جاهزة قريبة من 700$
A19: الباقة | B19: البند | C19: التكلفة/سنة ($) | D19: الإجمالي ($)
A20: باقة «إنتاج مستقر» — مُوصى بها | B20: الأساس (سنوات تالية) | C20: 219.36
B21: Supabase Pro | C21: 300
B22: مراقبة Uptime + Logs | C22: 120
B23: تخزين Bunny 100GB | C23: 66
B24: نسخ احتياطي D1 → R2 | C24: 2
A25: الإجمالي | D25: 707.36
A27: باقة «إنتاج + iOS» | B27: الأساس (سنوات تالية) | C27: 219.36
B28: Supabase Pro | C28: 300
B29: Apple Developer | C29: 99
B30: تخزين Bunny 100GB | C30: 66
B31: نسخ احتياطي D1 → R2 | C31: 2
A32: الإجمالي | D32: 686.36
A34: باقة «أداء + حماية» | B34: الأساس (سنوات تالية) | C34: 219.36
B35: Supabase Pro | C35: 300
B36: Cloudflare Pro للنطاق | C36: 240
B37: نسخ احتياطي D1 → R2 | C37: 2
A38: الإجمالي | D38: 761.36
A40: ثالثاً: نفس الرقم من تغيير الافتراضات فقط (بدون خدمات مدفوعة)
A41: التغيير في الافتراضات | B41: الزيادة/سنة ($) | C41: الإجمالي التراكمي ($)
A42: نقطة البداية | C42: 219.36
A43: الاحتفاظ 12 شهر متحرك (بدل حذف بنهاية السنة) | B43: 129.6 | C43: 348.96
A44: سحب Bunny بتسعير الشرق الأوسط (0.06$/GB) | B44: 75.6 | C44: 424.56
A45: بدون كاش حافة (كل القراءات من R2) | B45: 31.44 | C45: 456
A46: 10,000 طالب بدل 2,000 | B46: 13 | C46: 469
...
